Traceback (most recent call last):
  File "/Users/instructorzamora/miniconda3/envs/ml_venv/lib/python3.9/site-packages/jupyter_core/utils/__init__.py", line 154, in wrapped
    asyncio.get_running_loop()
RuntimeError: no running event loop

During handling of the above exception, another exception occurred:

Traceback (most recent call last):
  File "/Users/instructorzamora/miniconda3/envs/ml_venv/lib/python3.9/site-packages/jupyter_cache/executors/utils.py", line 58, in single_nb_execution
    executenb(
  File "/Users/instructorzamora/miniconda3/envs/ml_venv/lib/python3.9/site-packages/nbclient/client.py", line 1319, in execute
    return NotebookClient(nb=nb, resources=resources, km=km, **kwargs).execute()
  File "/Users/instructorzamora/miniconda3/envs/ml_venv/lib/python3.9/site-packages/jupyter_core/utils/__init__.py", line 158, in wrapped
    return loop.run_until_complete(inner)
  File "/Users/instructorzamora/miniconda3/envs/ml_venv/lib/python3.9/asyncio/base_events.py", line 647, in run_until_complete
    return future.result()
  File "/Users/instructorzamora/miniconda3/envs/ml_venv/lib/python3.9/site-packages/nbclient/client.py", line 709, in async_execute
    await self.async_execute_cell(
  File "/Users/instructorzamora/miniconda3/envs/ml_venv/lib/python3.9/site-packages/nbclient/client.py", line 1062, in async_execute_cell
    await self._check_raise_for_error(cell, cell_index, exec_reply)
  File "/Users/instructorzamora/miniconda3/envs/ml_venv/lib/python3.9/site-packages/nbclient/client.py", line 918, in _check_raise_for_error
    raise CellExecutionError.from_cell_and_msg(cell, exec_reply_content)
nbclient.exceptions.CellExecutionError: An error occurred while executing the following cell:
------------------
import pandas as pd
from ydata_profiling import ProfileReport

filename = '/Users/instructorzamora/GitHub/Proyecto_Dataviz/Datos_viz/Datos/datamanip/bank/bank-full.csv'
df = pd.read_csv(filename,sep=';')

profile = ProfileReport(df,title='Informe de los datos', explorative = True)
profile.to_notebook_iframe()
------------------


[0;31m---------------------------------------------------------------------------[0m
[0;31mModuleNotFoundError[0m                       Traceback (most recent call last)
Cell [0;32mIn[2], line 2[0m
[1;32m      1[0m [38;5;28;01mimport[39;00m[38;5;250m [39m[38;5;21;01mpandas[39;00m[38;5;250m [39m[38;5;28;01mas[39;00m[38;5;250m [39m[38;5;21;01mpd[39;00m
[0;32m----> 2[0m [38;5;28;01mfrom[39;00m[38;5;250m [39m[38;5;21;01mydata_profiling[39;00m[38;5;250m [39m[38;5;28;01mimport[39;00m ProfileReport
[1;32m      4[0m filename [38;5;241m=[39m [38;5;124m'[39m[38;5;124m/Users/instructorzamora/GitHub/Proyecto_Dataviz/Datos_viz/Datos/datamanip/bank/bank-full.csv[39m[38;5;124m'[39m
[1;32m      5[0m df [38;5;241m=[39m pd[38;5;241m.[39mread_csv(filename,sep[38;5;241m=[39m[38;5;124m'[39m[38;5;124m;[39m[38;5;124m'[39m)

[0;31mModuleNotFoundError[0m: No module named 'ydata_profiling'

